DEBUG:root:Received request:
image_mean: 128.0
image_stddev: 33.0
model_name: "feedback_hgru_v5_3l_notemp_f_v4.ConvStack3DFFNModel"
model_args: "{\"depth\": 12, \"fov_size\": [64, 64, 16], \"deltas\": [15, 15, 3]}"
model_checkpoint_path: "/media/data_cifs/connectomics/ffn_ckpts/64_fov/feedback_hgru_v5_3l_notemp_f_v4_berson4x_w_inf_memb_r0/model.ckpt-225915"
inference_options {
  init_activation: 0.949999988079
  pad_value: 0.0500000007451
  move_threshold: 0.649999976158
  min_boundary_dist {
    x: 1
    y: 1
    z: 1
  }
  segment_threshold: 0.5
  min_segment_size: 100
}
segmentation_output_dir: "/media/data_cifs/connectomics/ding_segmentations/x0014/y0060/z0012/v1/"
seed_policy: "PolicyMembrane"
image {
  hdf5: "/media/data_cifs/connectomics/mag1_membranes/x0014/y0060/z0012/110629_k0725_mag1_x0014_y0060_z0012.raw.npy"
}

ERROR:root:Failed segmentation: [Errno 2] No such file or directory: u'/media/data_cifs/connectomics/mag1_membranes/x0014/y0060/z0012/110629_k0725_mag1_x0014_y0060_z0012.raw.npy'
Traceback (most recent call last):
  File "run_job.py", line 65, in main
    seed_policy=seed_policy)
  File "/media/data_cifs/cluster_projects/ffn_membrane_v2/hybrid_inference.py", line 274, in get_segmentation
    runner.start(req, tag='_inference')
  File "/media/data_cifs/cluster_projects/ffn_membrane_v2/ffn/inference/inference.py", line 964, in start
    cache_compression=False)
  File "/media/data_cifs/cluster_projects/ffn_membrane_v2/ffn/inference/storage.py", line 206, in decorated_volume
    volume = np.load(path[0])
  File "/usr/local/lib/python2.7/dist-packages/numpy/lib/npyio.py", line 372, in load
    fid = open(file, "rb")
IOError: [Errno 2] No such file or directory: u'/media/data_cifs/connectomics/mag1_membranes/x0014/y0060/z0012/110629_k0725_mag1_x0014_y0060_z0012.raw.npy'
